Workbook

Sheet INPUT_VENTA
A2: Mes | B2: Mayo
A3: Nombre prenda
A4: Talla
A5: Propietario prenda
A6: Vendedor
A7: Precio venta (BRUTO)
A8: Tipo de pago
A9: Marca (Tienda/externa)
A10: Observaciones

Sheet Precios
A1: SEASON | C1: $ | D1: nube | F1: $ | G1: SCAMMERS | I1: $ | J1: POP DISASTER | L1: $
A2: SHORTS | D2: HOODIE | F2: 35000 | J2: IDIOT | L2: 25000
A3: PANTALONES | C3: 75000 | D3: POLERON ZIP | F3: 40000 | J3: MILEY | L3: 25000
A4: MANGA LARGA | D4: BUZO | F4: 30000 | J4: RATA FOUNDRY | L4: 25000
A5: BBY TEE | C5: 20000 | D5: JEANS | F5: 42000 | J5: PATOS FOUNDRY | L5: 25000
A6: TAK TOP | C6: 25000 | D6: POLERON JAPON | F6: 36000
D7: POLERA JAPON | F7: 23000
D8: TAKASHI CLOUT | F8: 40000
D9: HOODIE BORDADO (ROJO Y NEGRO) | F9: 40000
D10: NUBENZ | F10: 45000

Sheet Pagos
A1: Pagos y saldos mensuales
A3: Resumen Tienda - Enero
A4: Concepto | B4: Valor (CLP)
A5: Neto total tienda (todas las ventas) | B5: =SUM(Enero!$M$4:Enero!$M$103) -> 0
A6: Neto prendas 'Tienda' (propietario) | B6: =SUMIF(Enero!$C$4:$C$103,"Tienda",Enero!$M$4:$M$103) -> 0
A7: Neto prendas 'Consignacion' (propietario) | B7: =SUMIF(Enero!$C$4:$C$103,"Consignacion",Enero!$M$4:$M$103) -> 0
A8: Total gastos fijos | B8: =Enero!$B$130 -> 1751960
A9: Gasto fijo por integrante (÷5) | B9: =Enero!$B$131 -> 350392
A11: Pagos fundadores - Enero
A12: Integrante | B12: Neto prendas propias | C12: Cuota gastos fijos | D12: Saldo final (a pagar / a depositar) | E12: Reembolso gastos personales
A13: Aaron | B13: =SUMIF(Enero!$C$4:$C$103,A13,Enero!$M$4:$M$103) -> 0 | C13: =$B$9 -> 350392 | D13: =B13-C13+E13 -> -350392 | E13: =SUMIFS(Gastos_Personales!$D:$D,Gastos_Personales!$E:$E,A13,Gastos_Personales!$A:$A,"Enero") -> 0
A14: Benja R | B14: =SUMIF(Enero!$C$4:$C$103,A14,Enero!$M$4:$M$103) -> 0 | C14: =$B$9 -> 350392 | D14: =B14-C14+E14 -> -350392 | E14: =SUMIFS(Gastos_Personales!$D:$D,Gastos_Personales!$E:$E,A14,Gastos_Personales!$A:$A,"Enero") -> 0
A15: Benja M | B15: =SUMIF(Enero!$C$4:$C$103,A15,Enero!$M$4:$M$103) -> 0 | C15: =$B$9 -> 350392 | D15: =B15-C15+E15 -> -350392 | E15: =SUMIFS(Gastos_Personales!$D:$D,Gastos_Personales!$E:$E,A15,Gastos_Personales!$A:$A,"Enero") -> 0
A16: Juanito | B16: =SUMIF(Enero!$C$4:$C$103,A16,Enero!$M$4:$M$103) -> 0 | C16: =$B$9 -> 350392 | D16: =B16-C16+E16 -> -350392 | E16: =SUMIFS(Gastos_Personales!$D:$D,Gastos_Personales!$E:$E,A16,Gastos_Personales!$A:$A,"Enero") -> 0
A17: Fabio | B17: =SUMIF(Enero!$C$4:$C$103,A17,Enero!$M$4:$M$103) -> 0 | C17: =$B$9 -> 350392 | D17: =B17-C17+E17 -> -350392 | E17: =SUMIFS(Gastos_Personales!$D:$D,Gastos_Personales!$E:$E,A17,Gastos_Personales!$A:$A,"Enero") -> 0
A19: Marcas externas - Enero
A20: Marca | B20: Ventas brutas marca | C20: Base comisión tienda (neto base) | D20: % comisión tienda | E20: Comisión tienda ($) | F20: IVA total marca
A21: =Marcas!$A$2 -> Nube | B21: =IF(A21="","",SUMIF(Enero!$O$4:$O$103,A21,Enero!$E$4:$E$103)) -> 0 | C21: =IF(A21="","",SUMIF(Enero!$O$4:$O$103,A21,Enero!$J$4:$J$103)) -> 0 | D21: =IF(A21="","",Marcas!$B$2) -> 0.25 | E21: =IF(A21="","",C21*D21) -> 0 | F21: =IF(A21="","",SUMIF(Enero!$O$4:$O$103,A21,Enero!$G$4:$G$103)) -> 0
A22: =Marcas!$A$3 -> Season Archive | B22: =IF(A22="","",SUMIF(Enero!$O$4:$O$103,A22,Enero!$E$4:$E$103)) -> 0 | C22: =IF(A22="","",SUMIF(Enero!$O$4:$O$103,A22,Enero!$J$4:$J$103)) -> 0 | D22: =IF(A22="","",Marcas!$B$3) -> 0.25 | E22: =IF(A22="","",C22*D22) -> 0 | F22: =IF(A22="","",SUMIF(Enero!$O$4:$O$103,A22,Enero!$G$4:$G$103)) -> 0
A23: =Marcas!$A$4 -> Gelattos | B23: =IF(A23="","",SUMIF(Enero!$O$4:$O$103,A23,Enero!$E$4:$E$103)) -> 0 | C23: =IF(A23="","",SUMIF(Enero!$O$4:$O$103,A23,Enero!$J$4:$J$103)) -> 0 | D23: =IF(A23="","",Marcas!$B$4) -> 0.25 | E23: =IF(A23="","",C23*D23) -> 0 | F23: =IF(A23="","",SUMIF(Enero!$O$4:$O$103,A23,Enero!$G$4:$G$103)) -> 0
A24: =Marcas!$A$5 -> Tienda | B24: =IF(A24="","",SUMIF(Enero!$O$4:$O$103,A24,Enero!$E$4:$E$103)) -> 0 | C24: =IF(A24="","",SUMIF(Enero!$O$4:$O$103,A24,Enero!$J$4:$J$103)) -> 0 | D24: =IF(A24="","",Marcas!$B$5) -> 0 | E24: =IF(A24="","",C24*D24) -> 0 | F24: =IF(A24="","",SUMIF(Enero!$O$4:$O$103,A24,Enero!$G$4:$G$103)) -> 0
A25: =Marcas!$A$6 -> Pop disaster | B25: =IF(A25="","",SUMIF(Enero!$O$4:$O$103,A25,Enero!$E$4:$E$103)) -> 0 | C25: =IF(A25="","",SUMIF(Enero!$O$4:$O$103,A25,Enero!$J$4:$J$103)) -> 0 | D25: =IF(A25="","",Marcas!$B$6) -> 0.25 | E25: =IF(A25="","",C25*D25) -> 0 | F25: =IF(A25="","",SUMIF(Enero!$O$4:$O$103,A25,Enero!$G$4:$G$103)) -> 0
A26: =Marcas!$A$7 -> Pedritos | B26: =IF(A26="","",SUMIF(Enero!$O$4:$O$103,A26,Enero!$E$4:$E$103)) -> 0 | C26: =IF(A26="","",SUMIF(Enero!$O$4:$O$103,A26,Enero!$J$4:$J$103)) -> 0 | D26: =IF(A26="","",Marcas!$B$7) -> 0.25 | E26: =IF(A26="","",C26*D26) -> 0 | F26: =IF(A26="","",SUMIF(Enero!$O$4:$O$103,A26,Enero!$G$4:$G$103)) -> 0
A27: =Marcas!$A$8 | B27: =IF(A27="","",SUMIF(Enero!$O$4:$O$103,A27,Enero!$E$4:$E$103)) | C27: =IF(A27="","",SUMIF(Enero!$O$4:$O$103,A27,Enero!$J$4:$J$103)) | D27: =IF(A27="","",Marcas!$B$8) | E27: =IF(A27="","",C27*D27) | F27: =IF(A27="","",SUMIF(Enero!$O$4:$O$103,A27,Enero!$G$4:$G$103))
A28: =Marcas!$A$9 | B28: =IF(A28="","",SUMIF(Enero!$O$4:$O$103,A28,Enero!$E$4:$E$103)) | C28: =IF(A28="","",SUMIF(Enero!$O$4:$O$103,A28,Enero!$J$4:$J$103)) | D28: =IF(A28="","",Marcas!$B$9) | E28: =IF(A28="","",C28*D28) | F28: =IF(A28="","",SUMIF(Enero!$O$4:$O$103,A28,Enero!$G$4:$G$103))
A29: =Marcas!$A$10 | B29: =IF(A29="","",SUMIF(Enero!$O$4:$O$103,A29,Enero!$E$4:$E$103)) | C29: =IF(A29="","",SUMIF(Enero!$O$4:$O$103,A29,Enero!$J$4:$J$103)) | D29: =IF(A29="","",Marcas!$B$10) | E29: =IF(A29="","",C29*D29) | F29: =IF(A29="","",SUMIF(Enero!$O$4:$O$103,A29,Enero!$G$4:$G$103))
A30: =Marcas!$A$11 | B30: =IF(A30="","",SUMIF(Enero!$O$4:$O$103,A30,Enero!$E$4:$E$103)) | C30: =IF(A30="","",SUMIF(Enero!$O$4:$O$103,A30,Enero!$J$4:$J$103)) | D30: =IF(A30="","",Marcas!$B$11) | E30: =IF(A30="","",C30*D30) | F30: =IF(A30="","",SUMIF(Enero!$O$4:$O$103,A30,Enero!$G$4:$G$103))
A34: Resumen Tienda - Febrero
A35: Concepto | B35: Valor (CLP)
A36: Neto total tienda (todas las ventas) | B36: =SUM(Febrero!$M$4:Febrero!$M$103) -> 2546018.7
A37: Neto prendas 'Tienda' (propietario) | B37: =SUMIF(Febrero!$C$4:$C$103,"Tienda",Febrero!$M$4:$M$103) -> 727487.89
A38: Neto prendas 'Consignacion' (propietario) | B38: =SUMIF(Febrero!$C$4:$C$103,"Consignacion",Febrero!$M$4:$M$103) -> 363200
A39: Total gastos fijos | B39: =Febrero!$B$130 -> 1751960
A40: Gasto fijo por integrante (÷5) | B40: =Febrero!$B$131 -> 350392
A42: Pagos fundadores - Febrero
A43: Integrante | B43: Neto prendas propias | C43: Cuota gastos fijos | D43: Saldo final (a pagar / a depositar)
A44: Aaron | B44: =SUMIF(Febrero!$C$4:$C$103,A44,Febrero!$M$4:$M$103) -> 186000 | C44: =$B$40 -> 350392 | D44: =B44-C44 -> -164392
A45: Benja R | B45: =SUMIF(Febrero!$C$4:$C$103,A45,Febrero!$M$4:$M$103) -> 969870.8 | C45: =$B$40 -> 350392 | D45: =B45-C45 -> 619478.8
A46: Benja M | B46: =SUMIF(Febrero!$C$4:$C$103,A46,Febrero!$M$4:$M$103) -> 0 | C46: =$B$40 -> 350392 | D46: =B46-C46 -> -350392
A47: Juanito | B47: =SUMIF(Febrero!$C$4:$C$103,A47,Febrero!$M$4:$M$103) -> 0 | C47: =$B$40 -> 350392 | D47: =B47-C47 -> -350392
...

Sheet Gastos_Personales
A1: Mes | B1: Fecha | C1: Concepto | D1: Monto CLP | E1: Pagado por
A2: noviembre | C2: Computador ventas | D2: 50000 | E2: no

Sheet Comisiones
A1: Comisiones por vendedor y mes
A3: Comisiones - Enero
A4: Vendedor | B4: Total bruto ventas | C4: Total IVA | D4: Total comisiones bancarias | E4: Total comisiones vendedor | F4: Total neto tienda | G4: Nº ventas | H4: Ticket prom (bruto)
A5: Aaron | B5: =SUMIF(Enero!$D$4:Enero!$D$103,A5,Enero!$E$4:Enero!$E$103) -> 0 | C5: =SUMIF(Enero!$D$4:Enero!$D$103,A5,Enero!$G$4:Enero!$G$103) -> 0 | D5: =SUMIF(Enero!$D$4:Enero!$D$103,A5,Enero!$I$4:Enero!$I$103) -> 0 | E5: =SUMIF(Enero!$D$4:Enero!$D$103,A5,Enero!$L$4:Enero!$L$103) -> 0 | F5: =SUMIF(Enero!$D$4:Enero!$D$103,A5,Enero!$M$4:Enero!$M$103) -> 0 | G5: =COUNTIF(Enero!$D$4:Enero!$D$103,A5) -> 0 | H5: =IF(G5=0,0,B5/G5) -> 0
A6: Benja R | B6: =SUMIF(Enero!$D$4:Enero!$D$103,A6,Enero!$E$4:Enero!$E$103) -> 0 | C6: =SUMIF(Enero!$D$4:Enero!$D$103,A6,Enero!$G$4:Enero!$G$103) -> 0 | D6: =SUMIF(Enero!$D$4:Enero!$D$103,A6,Enero!$I$4:Enero!$I$103) -> 0 | E6: =SUMIF(Enero!$D$4:Enero!$D$103,A6,Enero!$L$4:Enero!$L$103) -> 0 | F6: =SUMIF(Enero!$D$4:Enero!$D$103,A6,Enero!$M$4:Enero!$M$103) -> 0 | G6: =COUNTIF(Enero!$D$4:Enero!$D$103,A6) -> 0 | H6: =IF(G6=0,0,B6/G6) -> 0
A7: Benja M | B7: =SUMIF(Enero!$D$4:Enero!$D$103,A7,Enero!$E$4:Enero!$E$103) -> 0 | C7: =SUMIF(Enero!$D$4:Enero!$D$103,A7,Enero!$G$4:Enero!$G$103) -> 0 | D7: =SUMIF(Enero!$D$4:Enero!$D$103,A7,Enero!$I$4:Enero!$I$103) -> 0 | E7: =SUMIF(Enero!$D$4:Enero!$D$103,A7,Enero!$L$4:Enero!$L$103) -> 0 | F7: =SUMIF(Enero!$D$4:Enero!$D$103,A7,Enero!$M$4:Enero!$M$103) -> 0 | G7: =COUNTIF(Enero!$D$4:Enero!$D$103,A7) -> 0 | H7: =IF(G7=0,0,B7/G7) -> 0
A8: Juanito | B8: =SUMIF(Enero!$D$4:Enero!$D$103,A8,Enero!$E$4:Enero!$E$103) -> 0 | C8: =SUMIF(Enero!$D$4:Enero!$D$103,A8,Enero!$G$4:Enero!$G$103) -> 0 | D8: =SUMIF(Enero!$D$4:Enero!$D$103,A8,Enero!$I$4:Enero!$I$103) -> 0 | E8: =SUMIF(Enero!$D$4:Enero!$D$103,A8,Enero!$L$4:Enero!$L$103) -> 0 | F8: =SUMIF(Enero!$D$4:Enero!$D$103,A8,Enero!$M$4:Enero!$M$103) -> 0 | G8: =COUNTIF(Enero!$D$4:Enero!$D$103,A8) -> 0 | H8: =IF(G8=0,0,B8/G8) -> 0
A9: Fabio | B9: =SUMIF(Enero!$D$4:Enero!$D$103,A9,Enero!$E$4:Enero!$E$103) -> 0 | C9: =SUMIF(Enero!$D$4:Enero!$D$103,A9,Enero!$G$4:Enero!$G$103) -> 0 | D9: =SUMIF(Enero!$D$4:Enero!$D$103,A9,Enero!$I$4:Enero!$I$103) -> 0 | E9: =SUMIF(Enero!$D$4:Enero!$D$103,A9,Enero!$L$4:Enero!$L$103) -> 0 | F9: =SUMIF(Enero!$D$4:Enero!$D$103,A9,Enero!$M$4:Enero!$M$103) -> 0 | G9: =COUNTIF(Enero!$D$4:Enero!$D$103,A9) -> 0 | H9: =IF(G9=0,0,B9/G9) -> 0
A10: Marenna | B10: =SUMIF(Enero!$D$4:Enero!$D$103,A10,Enero!$E$4:Enero!$E$103) -> 0 | C10: =SUMIF(Enero!$D$4:Enero!$D$103,A10,Enero!$G$4:Enero!$G$103) -> 0 | D10: =SUMIF(Enero!$D$4:Enero!$D$103,A10,Enero!$I$4:Enero!$I$103) -> 0 | E10: =SUMIF(Enero!$D$4:Enero!$D$103,A10,Enero!$L$4:Enero!$L$103) -> 0 | F10: =SUMIF(Enero!$D$4:Enero!$D$103,A10,Enero!$M$4:Enero!$M$103) -> 0 | G10: =COUNTIF(Enero!$D$4:Enero!$D$103,A10) -> 0 | H10: =IF(G10=0,0,B10/G10) -> 0
A11: Juan | B11: =SUMIF(Enero!$D$4:Enero!$D$103,A11,Enero!$E$4:Enero!$E$103) -> 0 | C11: =SUMIF(Enero!$D$4:Enero!$D$103,A11,Enero!$G$4:Enero!$G$103) -> 0 | D11: =SUMIF(Enero!$D$4:Enero!$D$103,A11,Enero!$I$4:Enero!$I$103) -> 0 | E11: =SUMIF(Enero!$D$4:Enero!$D$103,A11,Enero!$L$4:Enero!$L$103) -> 0 | F11: =SUMIF(Enero!$D$4:Enero!$D$103,A11,Enero!$M$4:Enero!$M$103) -> 0 | G11: =COUNTIF(Enero!$D$4:Enero!$D$103,A11) -> 0 | H11: =IF(G11=0,0,B11/G11) -> 0
A12: TOTAL | B12: =SUM(B5:B11) -> 0 | C12: =SUM(C5:C11) -> 0 | D12: =SUM(D5:D11) -> 0 | E12: =SUM(E5:E11) -> 0 | F12: =SUM(F5:F11) -> 0 | G12: =SUM(G5:G11) -> 0 | H12: =SUM(H5:H11) -> 0
A15: Comisiones - Febrero
A16: Vendedor | B16: Total bruto ventas | C16: Total IVA | D16: Total comisiones bancarias | E16: Total comisiones vendedor | F16: Total neto tienda | G16: Nº ventas | H16: Ticket prom (bruto)
A17: Aaron | B17: =SUMIF(Febrero!$D$4:Febrero!$D$103,A17,Febrero!$E$4:Febrero!$E$103) -> 175800 | C17: =SUMIF(Febrero!$D$4:Febrero!$D$103,A17,Febrero!$G$4:Febrero!$G$103) -> 0 | D17: =SUMIF(Febrero!$D$4:Febrero!$D$103,A17,Febrero!$I$4:Febrero!$I$103) -> 0 | E17: =SUMIF(Febrero!$D$4:Febrero!$D$103,A17,Febrero!$L$4:Febrero!$L$103) -> 12306 | F17: =SUMIF(Febrero!$D$4:Febrero!$D$103,A17,Febrero!$M$4:Febrero!$M$103) -> 163494 | G17: =COUNTIF(Febrero!$D$4:Febrero!$D$103,A17) -> 5 | H17: =IF(G17=0,0,B17/G17) -> 35160
A18: Benja R | B18: =SUMIF(Febrero!$D$4:Febrero!$D$103,A18,Febrero!$E$4:Febrero!$E$103) -> 1055800 | C18: =SUMIF(Febrero!$D$4:Febrero!$D$103,A18,Febrero!$G$4:Febrero!$G$103) -> 0 | D18: =SUMIF(Febrero!$D$4:Febrero!$D$103,A18,Febrero!$I$4:Febrero!$I$103) -> 0 | E18: =SUMIF(Febrero!$D$4:Febrero!$D$103,A18,Febrero!$L$4:Febrero!$L$103) -> 63756 | F18: =SUMIF(Febrero!$D$4:Febrero!$D$103,A18,Febrero!$M$4:Febrero!$M$103) -> 992044 | G18: =COUNTIF(Febrero!$D$4:Febrero!$D$103,A18) -> 27 | H18: =IF(G18=0,0,B18/G18) -> 39103.704
A19: Benja M | B19: =SUMIF(Febrero!$D$4:Febrero!$D$103,A19,Febrero!$E$4:Febrero!$E$103) -> 0 | C19: =SUMIF(Febrero!$D$4:Febrero!$D$103,A19,Febrero!$G$4:Febrero!$G$103) -> 0 | D19: =SUMIF(Febrero!$D$4:Febrero!$D$103,A19,Febrero!$I$4:Febrero!$I$103) -> 0 | E19: =SUMIF(Febrero!$D$4:Febrero!$D$103,A19,Febrero!$L$4:Febrero!$L$103) -> 0 | F19: =SUMIF(Febrero!$D$4:Febrero!$D$103,A19,Febrero!$M$4:Febrero!$M$103) -> 0 | G19: =COUNTIF(Febrero!$D$4:Febrero!$D$103,A19) -> 0 | H19: =IF(G19=0,0,B19/G19) -> 0
A20: Juanito | B20: =SUMIF(Febrero!$D$4:Febrero!$D$103,A20,Febrero!$E$4:Febrero!$E$103) -> 0 | C20: =SUMIF(Febrero!$D$4:Febrero!$D$103,A20,Febrero!$G$4:Febrero!$G$103) -> 0 | D20: =SUMIF(Febrero!$D$4:Febrero!$D$103,A20,Febrero!$I$4:Febrero!$I$103) -> 0 | E20: =SUMIF(Febrero!$D$4:Febrero!$D$103,A20,Febrero!$L$4:Febrero!$L$103) -> 0 | F20: =SUMIF(Febrero!$D$4:Febrero!$D$103,A20,Febrero!$M$4:Febrero!$M$103) -> 0 | G20: =COUNTIF(Febrero!$D$4:Febrero!$D$103,A20) -> 0 | H20: =IF(G20=0,0,B20/G20) -> 0
A21: Fabio | B21: =SUMIF(Febrero!$D$4:Febrero!$D$103,A21,Febrero!$E$4:Febrero!$E$103) -> 733000 | C21: =SUMIF(Febrero!$D$4:Febrero!$D$103,A21,Febrero!$G$4:Febrero!$G$103) -> 8781.5126 | D21: =SUMIF(Febrero!$D$4:Febrero!$D$103,A21,Febrero!$I$4:Febrero!$I$103) -> 1512.5 | E21: =SUMIF(Febrero!$D$4:Febrero!$D$103,A21,Febrero!$L$4:Febrero!$L$103) -> 23935.299 | F21: =SUMIF(Febrero!$D$4:Febrero!$D$103,A21,Febrero!$M$4:Febrero!$M$103) -> 698770.69 | G21: =COUNTIF(Febrero!$D$4:Febrero!$D$103,A21) -> 12 | H21: =IF(G21=0,0,B21/G21) -> 61083.333
A22: Marenna | B22: =SUMIF(Febrero!$D$4:Febrero!$D$103,A22,Febrero!$E$4:Febrero!$E$103) -> 737000 | C22: =SUMIF(Febrero!$D$4:Febrero!$D$103,A22,Febrero!$G$4:Febrero!$G$103) -> 0 | D22: =SUMIF(Febrero!$D$4:Febrero!$D$103,A22,Febrero!$I$4:Febrero!$I$103) -> 0 | E22: =SUMIF(Febrero!$D$4:Febrero!$D$103,A22,Febrero!$L$4:Febrero!$L$103) -> 45290 | F22: =SUMIF(Febrero!$D$4:Febrero!$D$103,A22,Febrero!$M$4:Febrero!$M$103) -> 691710 | G22: =COUNTIF(Febrero!$D$4:Febrero!$D$103,A22) -> 15 | H22: =IF(G22=0,0,B22/G22) -> 49133.333
A23: Juan | B23: =SUMIF(Febrero!$D$4:Febrero!$D$103,A23,Febrero!$E$4:Febrero!$E$103) -> 0 | C23: =SUMIF(Febrero!$D$4:Febrero!$D$103,A23,Febrero!$G$4:Febrero!$G$103) -> 0 | D23: =SUMIF(Febrero!$D$4:Febrero!$D$103,A23,Febrero!$I$4:Febrero!$I$103) -> 0 | E23: =SUMIF(Febrero!$D$4:Febrero!$D$103,A23,Febrero!$L$4:Febrero!$L$103) -> 0 | F23: =SUMIF(Febrero!$D$4:Febrero!$D$103,A23,Febrero!$M$4:Febrero!$M$103) -> 0 | G23: =COUNTIF(Febrero!$D$4:Febrero!$D$103,A23) -> 0 | H23: =IF(G23=0,0,B23/G23) -> 0
A24: TOTAL | B24: =SUM(B17:B23) -> 2701600 | C24: =SUM(C17:C23) -> 8781.5126 | D24: =SUM(D17:D23) -> 1512.5 | E24: =SUM(E17:E23) -> 145287.3 | F24: =SUM(F17:F23) -> 2546018.7 | G24: =SUM(G17:G23) -> 59 | H24: =SUM(H17:H23) -> 184480.37
A27: Comisiones - Marzo
A28: Vendedor | B28: Total bruto ventas | C28: Total IVA | D28: Total comisiones bancarias | E28: Total comisiones vendedor | F28: Total neto tienda | G28: Nº ventas | H28: Ticket prom (bruto)
A29: Aaron | B29: =SUMIF(Marzo!$D$4:Marzo!$D$103,A29,Marzo!$E$4:Marzo!$E$103) -> 55000 | C29: =SUMIF(Marzo!$D$4:Marzo!$D$103,A29,Marzo!$G$4:Marzo!$G$103) -> 5588.2353 | D29: =SUMIF(Marzo!$D$4:Marzo!$D$103,A29,Marzo!$I$4:Marzo!$I$103) -> 962.5 | E29: =SUMIF(Marzo!$D$4:Marzo!$D$103,A29,Marzo!$L$4:Marzo!$L$103) -> 1422.4632 | F29: =SUMIF(Marzo!$D$4:Marzo!$D$103,A29,Marzo!$M$4:Marzo!$M$103) -> 47026.801 | G29: =COUNTIF(Marzo!$D$4:Marzo!$D$103,A29) -> 2 | H29: =IF(G29=0,0,B29/G29) -> 27500
A30: Benja R | B30: =SUMIF(Marzo!$D$4:Marzo!$D$103,A30,Marzo!$E$4:Marzo!$E$103) -> 7355000 | C30: =SUMIF(Marzo!$D$4:Marzo!$D$103,A30,Marzo!$G$4:Marzo!$G$103) -> 11176.471 | D30: =SUMIF(Marzo!$D$4:Marzo!$D$103,A30,Marzo!$I$4:Marzo!$I$103) -> 1925 | E30: =SUMIF(Marzo!$D$4:Marzo!$D$103,A30,Marzo!$L$4:Marzo!$L$103) -> 407794.93 | F30: =SUMIF(Marzo!$D$4:Marzo!$D$103,A30,Marzo!$M$4:Marzo!$M$103) -> 6889103.6 | G30: =COUNTIF(Marzo!$D$4:Marzo!$D$103,A30) -> 62 | H30: =IF(G30=0,0,B30/G30) -> 118629.03
A31: Benja M | B31: =SUMIF(Marzo!$D$4:Marzo!$D$103,A31,Marzo!$E$4:Marzo!$E$103) -> 0 | C31: =SUMIF(Marzo!$D$4:Marzo!$D$103,A31,Marzo!$G$4:Marzo!$G$103) -> 0 | D31: =SUMIF(Marzo!$D$4:Marzo!$D$103,A31,Marzo!$I$4:Marzo!$I$103) -> 0 | E31: =SUMIF(Marzo!$D$4:Marzo!$D$103,A31,Marzo!$L$4:Marzo!$L$103) -> 0 | F31: =SUMIF(Marzo!$D$4:Marzo!$D$103,A31,Marzo!$M$4:Marzo!$M$103) -> 0 | G31: =COUNTIF(Marzo!$D$4:Marzo!$D$103,A31) -> 0 | H31: =IF(G31=0,0,B31/G31) -> 0
A32: Juanito | B32: =SUMIF(Marzo!$D$4:Marzo!$D$103,A32,Marzo!$E$4:Marzo!$E$103) -> 0 | C32: =SUMIF(Marzo!$D$4:Marzo!$D$103,A32,Marzo!$G$4:Marzo!$G$103) -> 0 | D32: =SUMIF(Marzo!$D$4:Marzo!$D$103,A32,Marzo!$I$4:Marzo!$I$103) -> 0 | E32: =SUMIF(Marzo!$D$4:Marzo!$D$103,A32,Marzo!$L$4:Marzo!$L$103) -> 0 | F32: =SUMIF(Marzo!$D$4:Marzo!$D$103,A32,Marzo!$M$4:Marzo!$M$103) -> 0 | G32: =COUNTIF(Marzo!$D$4:Marzo!$D$103,A32) -> 0 | H32: =IF(G32=0,0,B32/G32) -> 0
A33: Fabio | B33: =SUMIF(Marzo!$D$4:Marzo!$D$103,A33,Marzo!$E$4:Marzo!$E$103) -> 1525000 | C33: =SUMIF(Marzo!$D$4:Marzo!$D$103,A33,Marzo!$G$4:Marzo!$G$103) -> 9579.8319 | D33: =SUMIF(Marzo!$D$4:Marzo!$D$103,A33,Marzo!$I$4:Marzo!$I$103) -> 1650 | E33: =SUMIF(Marzo!$D$4:Marzo!$D$103,A33,Marzo!$L$4:Marzo!$L$103) -> 92388.508 | F33: =SUMIF(Marzo!$D$4:Marzo!$D$103,A33,Marzo!$M$4:Marzo!$M$103) -> 1421381.7 | G33: =COUNTIF(Marzo!$D$4:Marzo!$D$103,A33) -> 14 | H33: =IF(G33=0,0,B33/G33) -> 108928.57
A34: Marenna | B34: =SUMIF(Marzo!$D$4:Marzo!$D$103,A34,Marzo!$E$4:Marzo!$E$103) -> 590000 | C34: =SUMIF(Marzo!$D$4:Marzo!$D$103,A34,Marzo!$G$4:Marzo!$G$103) -> 0 | D34: =SUMIF(Marzo!$D$4:Marzo!$D$103,A34,Marzo!$I$4:Marzo!$I$103) -> 0 | E34: =SUMIF(Marzo!$D$4:Marzo!$D$103,A34,Marzo!$L$4:Marzo!$L$103) -> 35700 | F34: =SUMIF(Marzo!$D$4:Marzo!$D$103,A34,Marzo!$M$4:Marzo!$M$103) -> 554300 | G34: =COUNTIF(Marzo!$D$4:Marzo!$D$103,A34) -> 14 | H34: =IF(G34=0,0,B34/G34) -> 42142.857
A35: Juan | B35: =SUMIF(Marzo!$D$4:Marzo!$D$103,A35,Marzo!$E$4:Marzo!$E$103) -> 0 | C35: =SUMIF(Marzo!$D$4:Marzo!$D$103,A35,Marzo!$G$4:Marzo!$G$103) -> 0 | D35: =SUMIF(Marzo!$D$4:Marzo!$D$103,A35,Marzo!$I$4:Marzo!$I$103) -> 0 | E35: =SUMIF(Marzo!$D$4:Marzo!$D$103,A35,Marzo!$L$4:Marzo!$L$103) -> 0 | F35: =SUMIF(Marzo!$D$4:Marzo!$D$103,A35,Marzo!$M$4:Marzo!$M$103) -> 0 | G35: =COUNTIF(Marzo!$D$4:Marzo!$D$103,A35) -> 0 | H35: =IF(G35=0,0,B35/G35) -> 0
A36: TOTAL | B36: =SUM(B29:B35) -> 9525000 | C36: =SUM(C29:C35) -> 26344.538 | D36: =SUM(D29:D35) -> 4537.5 | E36: =SUM(E29:E35) -> 537305.9 | F36: =SUM(F29:F35) -> 8911812.1 | G36: =SUM(G29:G35) -> 92 | H36: =SUM(H29:H35) -> 297200.46
A39: Comisiones - Abril
A40: Vendedor | B40: Total bruto ventas | C40: Total IVA | D40: Total comisiones bancarias | E40: Total comisiones vendedor | F40: Total neto tienda | G40: Nº ventas | H40: Ticket prom (bruto)
A41: Aaron | B41: =SUMIF(Abril!$D$4:Abril!$D$103,A41,Abril!$E$4:Abril!$E$103) -> 160000 | C41: =SUMIF(Abril!$D$4:Abril!$D$103,A41,Abril!$G$4:Abril!$G$103) -> 12773.109 | D41: =SUMIF(Abril!$D$4:Abril!$D$103,A41,Abril!$I$4:Abril!$I$103) -> 2360 | E41: =SUMIF(Abril!$D$4:Abril!$D$103,A41,Abril!$L$4:Abril!$L$103) -> 0 | F41: =SUMIF(Abril!$D$4:Abril!$D$103,A41,Abril!$M$4:Abril!$M$103) -> 144866.89 | G41: =COUNTIF(Abril!$D$4:Abril!$D$103,A41) -> 3 | H41: =IF(G41=0,0,B41/G41) -> 53333.333
A42: Benja R | B42: =SUMIF(Abril!$D$4:Abril!$D$103,A42,Abril!$E$4:Abril!$E$103) -> 1878000 | C42: =SUMIF(Abril!$D$4:Abril!$D$103,A42,Abril!$G$4:Abril!$G$103) -> 31932.773 | D42: =SUMIF(Abril!$D$4:Abril!$D$103,A42,Abril!$I$4:Abril!$I$103) -> 5740 | E42: =SUMIF(Abril!$D$4:Abril!$D$103,A42,Abril!$L$4:Abril!$L$103) -> 101216.36 | F42: =SUMIF(Abril!$D$4:Abril!$D$103,A42,Abril!$M$4:Abril!$M$103) -> 1739110.9 | G42: =COUNTIF(Abril!$D$4:Abril!$D$103,A42) -> 23 | H42: =IF(G42=0,0,B42/G42) -> 81652.174
A43: Benja M | B43: =SUMIF(Abril!$D$4:Abril!$D$103,A43,Abril!$E$4:Abril!$E$103) -> 0 | C43: =SUMIF(Abril!$D$4:Abril!$D$103,A43,Abril!$G$4:Abril!$G$103) -> 0 | D43: =SUMIF(Abril!$D$4:Abril!$D$103,A43,Abril!$I$4:Abril!$I$103) -> 0 | E43: =SUMIF(Abril!$D$4:Abril!$D$103,A43,Abril!$L$4:Abril!$L$103) -> 0 | F43: =SUMIF(Abril!$D$4:Abril!$D$103,A43,Abril!$M$4:Abril!$M$103) -> 0 | G43: =COUNTIF(Abril!$D$4:Abril!$D$103,A43) -> 0 | H43: =IF(G43=0,0,B43/G43) -> 0
A44: Juanito | B44: =SUMIF(Abril!$D$4:Abril!$D$103,A44,Abril!$E$4:Abril!$E$103) -> 0 | C44: =SUMIF(Abril!$D$4:Abril!$D$103,A44,Abril!$G$4:Abril!$G$103) -> 0 | D44: =SUMIF(Abril!$D$4:Abril!$D$103,A44,Abril!$I$4:Abril!$I$103) -> 0 | E44: =SUMIF(Abril!$D$4:Abril!$D$103,A44,Abril!$L$4:Abril!$L$103) -> 0 | F44: =SUMIF(Abril!$D$4:Abril!$D$103,A44,Abril!$M$4:Abril!$M$103) -> 0 | G44: =COUNTIF(Abril!$D$4:Abril!$D$103,A44) -> 0 | H44: =IF(G44=0,0,B44/G44) -> 0
A45: Fabio | B45: =SUMIF(Abril!$D$4:Abril!$D$103,A45,Abril!$E$4:Abril!$E$103) -> 1350000 | C45: =SUMIF(Abril!$D$4:Abril!$D$103,A45,Abril!$G$4:Abril!$G$103) -> 0 | D45: =SUMIF(Abril!$D$4:Abril!$D$103,A45,Abril!$I$4:Abril!$I$103) -> 0 | E45: =SUMIF(Abril!$D$4:Abril!$D$103,A45,Abril!$L$4:Abril!$L$103) -> 86800 | F45: =SUMIF(Abril!$D$4:Abril!$D$103,A45,Abril!$M$4:Abril!$M$103) -> 1263200 | G45: =COUNTIF(Abril!$D$4:Abril!$D$103,A45) -> 16 | H45: =IF(G45=0,0,B45/G45) -> 84375
A46: Marenna | B46: =SUMIF(Abril!$D$4:Abril!$D$103,A46,Abril!$E$4:Abril!$E$103) -> 531000 | C46: =SUMIF(Abril!$D$4:Abril!$D$103,A46,Abril!$G$4:Abril!$G$103) -> 3193.2773 | D46: =SUMIF(Abril!$D$4:Abril!$D$103,A46,Abril!$I$4:Abril!$I$103) -> 550 | E46: =SUMIF(Abril!$D$4:Abril!$D$103,A46,Abril!$L$4:Abril!$L$103) -> 30982.836 | F46: =SUMIF(Abril!$D$4:Abril!$D$103,A46,Abril!$M$4:Abril!$M$103) -> 496273.89 | G46: =COUNTIF(Abril!$D$4:Abril!$D$103,A46) -> 13 | H46: =IF(G46=0,0,B46/G46) -> 40846.154
A47: Juan | B47: =SUMIF(Abril!$D$4:Abril!$D$103,A47,Abril!$E$4:Abril!$E$103) -> 0 | C47: =SUMIF(Abril!$D$4:Abril!$D$103,A47,Abril!$G$4:Abril!$G$103) -> 0 | D47: =SUMIF(Abril!$D$4:Abril!$D$103,A47,Abril!$I$4:Abril!$I$103) -> 0 | E47: =SUMIF(Abril!$D$4:Abril!$D$103,A47,Abril!$L$4:Abril!$L$103) -> 0 | F47: =SUMIF(Abril!$D$4:Abril!$D$103,A47,Abril!$M$4:Abril!$M$103) -> 0 | G47: =COUNTIF(Abril!$D$4:Abril!$D$103,A47) -> 0 | H47: =IF(G47=0,0,B47/G47) -> 0
...

Sheet Mayo
A1: Mayo - Ingresos
P2: Total ventas brutas | Q2: =SUM(E4:E103) -> 2795000
A3: Nombre prenda | B3: Talla | C3: Propietario prenda | D3: Vendedor | E3: Precio venta (BRUTO) | F3: Tipo de pago | G3: IVA (19%) | H3: % comisión bancaria | I3: $ comisión bancaria | J3: Base comisión vendedor | K3: % comisión vendedor | L3: $ comisión vendedor | M3: Neto tienda | N3: Observaciones | O3: Marca (Tienda/externa) | P3: Total IVA ventas | Q3: =SUM(G4:G103) -> 18361.345
A4: bufanda burberry | B4: os | C4: Tienda | D4: Benja R | E4: 95000 | F4: Transferencia | G4: =IF(OR(F4="Débito",F4="Crédito",F4="Internet(Shopify)"),E4*19/119,0) -> 0 | H4: =IF(F4="Débito",0.0275,IF(F4="Crédito",0.0295,0)) -> 0 | I4: =E4*H4 -> 0 | J4: =E4-G4-I4 -> 95000 | K4: =IF($O4<>"Tienda",0,IF(OR($F4="Débito",$F4="Crédito"),0.05,IF(OR($F4="Efectivo",$F4="Transferencia"),0.07,0))) -> 0.07 | L4: =IF($O4<>"Tienda",0,$J4*$K4) -> 6650 | M4: =E4-G4-I4-L4 -> 88350 | N4: pagar 50.000 | O4: Tienda | P4: Total comisiones bancarias | Q4: =SUM(I4:I103) -> 550
A5: ballerinas ferragamo | B5: 38 | C5: Tienda | D5: Benja R | E5: 80000 | F5: Transferencia | G5: =IF(OR(F5="Débito",F5="Crédito",F5="Internet(Shopify)"),E5*19/119,0) -> 0 | H5: =IF(F5="Débito",0.0275,IF(F5="Crédito",0.0295,0)) -> 0 | I5: =E5*H5 -> 0 | J5: =E5-G5-I5 -> 80000 | K5: =IF($O5<>"Tienda",0,IF(OR($F5="Débito",$F5="Crédito"),0.05,IF(OR($F5="Efectivo",$F5="Transferencia"),0.07,0))) -> 0.07 | L5: =IF($O5<>"Tienda",0,$J5*$K5) -> 5600 | M5: =E5-G5-I5-L5 -> 74400 | N5: pagar benja 15.000 | O5: Tienda | P5: Total comisiones vendedores (NO se divide) | Q5: =SUM(L4:L103) -> 156562.84
A6: lentes louis vuitton | B6: os | C6: Tienda | D6: Benja R | E6: 180000 | F6: Transferencia | G6: =IF(OR(F6="Débito",F6="Crédito",F6="Internet(Shopify)"),E6*19/119,0) -> 0 | H6: =IF(F6="Débito",0.0275,IF(F6="Crédito",0.0295,0)) -> 0 | I6: =E6*H6 -> 0 | J6: =E6-G6-I6 -> 180000 | K6: =IF($O6<>"Tienda",0,IF(OR($F6="Débito",$F6="Crédito"),0.05,IF(OR($F6="Efectivo",$F6="Transferencia"),0.07,0))) -> 0 | L6: =IF($O6<>"Tienda",0,$J6*$K6) -> 0 | M6: =E6-G6-I6-L6 -> 180000 | P6: Total neto tienda (NO se divide) | Q6: =SUM(M4:M103) -> 2619525.8
A7: zapatillas comme des garcon | B7: 37 | C7: Tienda | D7: Benja R | E7: 80000 | F7: Transferencia | G7: =IF(OR(F7="Débito",F7="Crédito",F7="Internet(Shopify)"),E7*19/119,0) -> 0 | H7: =IF(F7="Débito",0.0275,IF(F7="Crédito",0.0295,0)) -> 0 | I7: =E7*H7 -> 0 | J7: =E7-G7-I7 -> 80000 | K7: =IF($O7<>"Tienda",0,IF(OR($F7="Débito",$F7="Crédito"),0.05,IF(OR($F7="Efectivo",$F7="Transferencia"),0.07,0))) -> 0 | L7: =IF($O7<>"Tienda",0,$J7*$K7) -> 0 | M7: =E7-G7-I7-L7 -> 80000 | P7: Número de ventas | Q7: =COUNTA(E4:E103) -> 28
A8: polera jpg mesh | B8: L | C8: Tienda | D8: Benja R | E8: 95000 | F8: Transferencia | G8: =IF(OR(F8="Débito",F8="Crédito",F8="Internet(Shopify)"),E8*19/119,0) -> 0 | H8: =IF(F8="Débito",0.0275,IF(F8="Crédito",0.0295,0)) -> 0 | I8: =E8*H8 -> 0 | J8: =E8-G8-I8 -> 95000 | K8: =IF($O8<>"Tienda",0,IF(OR($F8="Débito",$F8="Crédito"),0.05,IF(OR($F8="Efectivo",$F8="Transferencia"),0.07,0))) -> 0.07 | L8: =IF($O8<>"Tienda",0,$J8*$K8) -> 6650 | M8: =E8-G8-I8-L8 -> 88350 | N8: pagar 40.000 vicente | O8: Tienda | P8: Ticket promedio (NETO) | Q8: =IF(Q7=0,0,Q6/Q7) -> 93554.494
A9: Cartera LV | C9: Tienda | D9: Benja R | E9: 95000 | F9: Internet(Shopify) | G9: =IF(OR(F9="Débito",F9="Crédito",F9="Internet(Shopify)"),E9*19/119,0) -> 15168.067 | H9: =IF(F9="Débito",0.0275,IF(F9="Crédito",0.0295,0)) -> 0 | I9: =E9*H9 -> 0 | J9: =E9-G9-I9 -> 79831.933 | K9: =IF($O9<>"Tienda",0,IF(OR($F9="Débito",$F9="Crédito"),0.05,IF(OR($F9="Efectivo",$F9="Transferencia"),0.07,0))) -> 0 | L9: =IF($O9<>"Tienda",0,$J9*$K9) -> 0 | M9: =E9-G9-I9-L9 -> 79831.933 | O9: Tienda | P9: Ventas débito (neto) | Q9: =SUMIF(F4:F103,"Débito",M4:M103) -> 15443.887
A10: Lentes Dior | C10: Tienda | D10: Benja R | E10: 280000 | F10: Transferencia | G10: =IF(OR(F10="Débito",F10="Crédito",F10="Internet(Shopify)"),E10*19/119,0) -> 0 | H10: =IF(F10="Débito",0.0275,IF(F10="Crédito",0.0295,0)) -> 0 | I10: =E10*H10 -> 0 | J10: =E10-G10-I10 -> 280000 | K10: =IF($O10<>"Tienda",0,IF(OR($F10="Débito",$F10="Crédito"),0.05,IF(OR($F10="Efectivo",$F10="Transferencia"),0.07,0))) -> 0.07 | L10: =IF($O10<>"Tienda",0,$J10*$K10) -> 19600 | M10: =E10-G10-I10-L10 -> 260400 | O10: Tienda | P10: Ventas crédito (neto) | Q10: =SUMIF(F4:F103,"Crédito",M4:M103) -> 0
A11: Lentes LV | C11: Tienda | D11: Fabio | E11: 350000 | F11: Transferencia | G11: =IF(OR(F11="Débito",F11="Crédito",F11="Internet(Shopify)"),E11*19/119,0) -> 0 | H11: =IF(F11="Débito",0.0275,IF(F11="Crédito",0.0295,0)) -> 0 | I11: =E11*H11 -> 0 | J11: =E11-G11-I11 -> 350000 | K11: =IF($O11<>"Tienda",0,IF(OR($F11="Débito",$F11="Crédito"),0.05,IF(OR($F11="Efectivo",$F11="Transferencia"),0.07,0))) -> 0.07 | L11: =IF($O11<>"Tienda",0,$J11*$K11) -> 24500 | M11: =E11-G11-I11-L11 -> 325500 | N11: Moai Influencer 220.000 | O11: Tienda | P11: Ventas efectivo (neto) | Q11: =SUMIF(F4:F103,"Efectivo",M4:M103) -> 0
A12: Billetera VVW | C12: Fabio | D12: Benja R | E12: 120000 | F12: Transferencia | G12: =IF(OR(F12="Débito",F12="Crédito",F12="Internet(Shopify)"),E12*19/119,0) -> 0 | H12: =IF(F12="Débito",0.0275,IF(F12="Crédito",0.0295,0)) -> 0 | I12: =E12*H12 -> 0 | J12: =E12-G12-I12 -> 120000 | K12: =IF($O12<>"Tienda",0,IF(OR($F12="Débito",$F12="Crédito"),0.05,IF(OR($F12="Efectivo",$F12="Transferencia"),0.07,0))) -> 0.07 | L12: =IF($O12<>"Tienda",0,$J12*$K12) -> 8400 | M12: =E12-G12-I12-L12 -> 111600 | O12: Tienda | P12: Ventas transferencia (neto) | Q12: =SUMIF(F4:F103,"Transferencia",M4:M103) -> 2524250
A13: Billetera VVW | C13: Tienda | D13: Benja R | E13: 60000 | F13: Transferencia | G13: =IF(OR(F13="Débito",F13="Crédito",F13="Internet(Shopify)"),E13*19/119,0) -> 0 | H13: =IF(F13="Débito",0.0275,IF(F13="Crédito",0.0295,0)) -> 0 | I13: =E13*H13 -> 0 | J13: =E13-G13-I13 -> 60000 | K13: =IF($O13<>"Tienda",0,IF(OR($F13="Débito",$F13="Crédito"),0.05,IF(OR($F13="Efectivo",$F13="Transferencia"),0.07,0))) -> 0.07 | L13: =IF($O13<>"Tienda",0,$J13*$K13) -> 4200 | M13: =E13-G13-I13-L13 -> 55800 | O13: Tienda | P13: Ventas Internet(Shopify) (neto) | Q13: =SUMIF(F4:F103,"Internet(Shopify)",M4:M103) -> 79831.933
A14: Polera Bully | B14: M | C14: Tienda | D14: Benja R | E14: 25000 | F14: Transferencia | G14: =IF(OR(F14="Débito",F14="Crédito",F14="Internet(Shopify)"),E14*19/119,0) -> 0 | H14: =IF(F14="Débito",0.0275,IF(F14="Crédito",0.0295,0)) -> 0 | I14: =E14*H14 -> 0 | J14: =E14-G14-I14 -> 25000 | K14: =IF($O14<>"Tienda",0,IF(OR($F14="Débito",$F14="Crédito"),0.05,IF(OR($F14="Efectivo",$F14="Transferencia"),0.07,0))) -> 0 | L14: =IF($O14<>"Tienda",0,$J14*$K14) -> 0 | M14: =E14-G14-I14-L14 -> 25000 | N14: Pop Disaster 18.750 | O14: Pop disaster | P14: Ventas cuenta común (D+C+T) NETO | Q14: =SUMIF(F4:F103,"Débito",M4:M103)+SUMIF(F4:F103,"Crédito",M4:M103)+SUMIF(F4:F103,"Transferencia",M4:M103) -> 2539693.9
A15: Jacket Y-3 | C15: Consignacion | D15: Aaron | E15: 95000 | F15: Transferencia | G15: =IF(OR(F15="Débito",F15="Crédito",F15="Internet(Shopify)"),E15*19/119,0) -> 0 | H15: =IF(F15="Débito",0.0275,IF(F15="Crédito",0.0295,0)) -> 0 | I15: =E15*H15 -> 0 | J15: =E15-G15-I15 -> 95000 | K15: =IF($O15<>"Tienda",0,IF(OR($F15="Débito",$F15="Crédito"),0.05,IF(OR($F15="Efectivo",$F15="Transferencia"),0.07,0))) -> 0.07 | L15: =IF($O15<>"Tienda",0,$J15*$K15) -> 6650 | M15: =E15-G15-I15-L15 -> 88350 | N15: Pagar 20.000 amigo Julian | O15: Tienda | P15: IVA compras (manual)
A16: Polera Evisu | C16: Tienda | D16: Aaron | E16: 15000 | F16: Transferencia | G16: =IF(OR(F16="Débito",F16="Crédito",F16="Internet(Shopify)"),E16*19/119,0) -> 0 | H16: =IF(F16="Débito",0.0275,IF(F16="Crédito",0.0295,0)) -> 0 | I16: =E16*H16 -> 0 | J16: =E16-G16-I16 -> 15000 | K16: =IF($O16<>"Tienda",0,IF(OR($F16="Débito",$F16="Crédito"),0.05,IF(OR($F16="Efectivo",$F16="Transferencia"),0.07,0))) -> 0.07 | L16: =IF($O16<>"Tienda",0,$J16*$K16) -> 1050 | M16: =E16-G16-I16-L16 -> 13950 | O16: Tienda | P16: IVA neto (ventas - compras) | Q16: =Q3-Q15 -> 18361.345
A17: Sweater MMG Maison Margiela | B17: M | C17: Tienda | D17: Benja R | E17: 300000 | F17: Transferencia | G17: =IF(OR(F17="Débito",F17="Crédito",F17="Internet(Shopify)"),E17*19/119,0) -> 0 | H17: =IF(F17="Débito",0.0275,IF(F17="Crédito",0.0295,0)) -> 0 | I17: =E17*H17 -> 0 | J17: =E17-G17-I17 -> 300000 | K17: =IF($O17<>"Tienda",0,IF(OR($F17="Débito",$F17="Crédito"),0.05,IF(OR($F17="Efectivo",$F17="Transferencia"),0.07,0))) -> 0.07 | L17: =IF($O17<>"Tienda",0,$J17*$K17) -> 21000 | M17: =E17-G17-I17-L17 -> 279000 | O17: Tienda | P17: TOTAL PAGOS/CONSIGNACION/MARCAS | Q17: =50000+15000+40000+220000+18750+20000+15000+22500+45000+15000 -> 461250
A18: Chaqueta Diesel | B18: L | C18: Tienda | D18: Benja R | E18: 80000 | F18: Transferencia | G18: =IF(OR(F18="Débito",F18="Crédito",F18="Internet(Shopify)"),E18*19/119,0) -> 0 | H18: =IF(F18="Débito",0.0275,IF(F18="Crédito",0.0295,0)) -> 0 | I18: =E18*H18 -> 0 | J18: =E18-G18-I18 -> 80000 | K18: =IF($O18<>"Tienda",0,IF(OR($F18="Débito",$F18="Crédito"),0.05,IF(OR($F18="Efectivo",$F18="Transferencia"),0.07,0))) -> 0.07 | L18: =IF($O18<>"Tienda",0,$J18*$K18) -> 5600 | M18: =E18-G18-I18-L18 -> 74400 | O18: Tienda | P18: Total Liquido | Q18: =Q6-Q17 -> 2158275.8
A19: Camiseta Dormund | C19: Fabio | D19: Benja R | E19: 20000 | F19: Débito | G19: =IF(OR(F19="Débito",F19="Crédito",F19="Internet(Shopify)"),E19*19/119,0) -> 3193.2773 | H19: =IF(F19="Débito",0.0275,IF(F19="Crédito",0.0295,0)) -> 0.0275 | I19: =E19*H19 -> 550 | J19: =E19-G19-I19 -> 16256.723 | K19: =IF($O19<>"Tienda",0,IF(OR($F19="Débito",$F19="Crédito"),0.05,IF(OR($F19="Efectivo",$F19="Transferencia"),0.07,0))) -> 0.05 | L19: =IF($O19<>"Tienda",0,$J19*$K19) -> 812.83613 | M19: =E19-G19-I19-L19 -> 15443.887 | O19: Tienda
A20: Cinturon D&G | C20: Tienda | D20: Benja R | E20: 120000 | F20: Transferencia | G20: =IF(OR(F20="Débito",F20="Crédito",F20="Internet(Shopify)"),E20*19/119,0) -> 0 | H20: =IF(F20="Débito",0.0275,IF(F20="Crédito",0.0295,0)) -> 0 | I20: =E20*H20 -> 0 | J20: =E20-G20-I20 -> 120000 | K20: =IF($O20<>"Tienda",0,IF(OR($F20="Débito",$F20="Crédito"),0.05,IF(OR($F20="Efectivo",$F20="Transferencia"),0.07,0))) -> 0.07 | L20: =IF($O20<>"Tienda",0,$J20*$K20) -> 8400 | M20: =E20-G20-I20-L20 -> 111600 | O20: Tienda
A21: Bufanda Gris Negra | B21: s | C21: Tienda | D21: Benja R | E21: 20000 | F21: Transferencia | G21: =IF(OR(F21="Débito",F21="Crédito",F21="Internet(Shopify)"),E21*19/119,0) -> 0 | H21: =IF(F21="Débito",0.0275,IF(F21="Crédito",0.0295,0)) -> 0 | I21: =E21*H21 -> 0 | J21: =E21-G21-I21 -> 20000 | K21: =IF($O21<>"Tienda",0,IF(OR($F21="Débito",$F21="Crédito"),0.05,IF(OR($F21="Efectivo",$F21="Transferencia"),0.07,0))) -> 0 | L21: =IF($O21<>"Tienda",0,$J21*$K21) -> 0 | M21: =E21-G21-I21-L21 -> 20000 | N21: Pop Disaster 15.000 | O21: Pop disaster
A22: Polera Sin Mangas | B22: s | C22: Tienda | D22: Benja R | E22: 30000 | F22: Transferencia | G22: =IF(OR(F22="Débito",F22="Crédito",F22="Internet(Shopify)"),E22*19/119,0) -> 0 | H22: =IF(F22="Débito",0.0275,IF(F22="Crédito",0.0295,0)) -> 0 | I22: =E22*H22 -> 0 | J22: =E22-G22-I22 -> 30000 | K22: =IF($O22<>"Tienda",0,IF(OR($F22="Débito",$F22="Crédito"),0.05,IF(OR($F22="Efectivo",$F22="Transferencia"),0.07,0))) -> 0 | L22: =IF($O22<>"Tienda",0,$J22*$K22) -> 0 | M22: =E22-G22-I22-L22 -> 30000 | N22: Pedritos 22.500 | O22: Pedritos
A23: Crewneck Acne Studio | B23: Xl | C23: Tienda | E23: 90000 | F23: Transferencia | G23: =IF(OR(F23="Débito",F23="Crédito",F23="Internet(Shopify)"),E23*19/119,0) -> 0 | H23: =IF(F23="Débito",0.0275,IF(F23="Crédito",0.0295,0)) -> 0 | I23: =E23*H23 -> 0 | J23: =E23-G23-I23 -> 90000 | K23: =IF($O23<>"Tienda",0,IF(OR($F23="Débito",$F23="Crédito"),0.05,IF(OR($F23="Efectivo",$F23="Transferencia"),0.07,0))) -> 0.07 | L23: =IF($O23<>"Tienda",0,$J23*$K23) -> 6300 | M23: =E23-G23-I23-L23 -> 83700 | N23: Michelle | O23: Tienda
A24: Pulsera Plata | B24: os | C24: Fabio | E24: 30000 | F24: Transferencia | G24: =IF(OR(F24="Débito",F24="Crédito",F24="Internet(Shopify)"),E24*19/119,0) -> 0 | H24: =IF(F24="Débito",0.0275,IF(F24="Crédito",0.0295,0)) -> 0 | I24: =E24*H24 -> 0 | J24: =E24-G24-I24 -> 30000 | K24: =IF($O24<>"Tienda",0,IF(OR($F24="Débito",$F24="Crédito"),0.05,IF(OR($F24="Efectivo",$F24="Transferencia"),0.07,0))) -> 0.07 | L24: =IF($O24<>"Tienda",0,$J24*$K24) -> 2100 | M24: =E24-G24-I24-L24 -> 27900 | N24: Michelle | O24: Tienda
A25: Jack Cactus Polera | B25: L | C25: Tienda | D25: Marenna | E25: 30000 | F25: Transferencia | G25: =IF(OR(F25="Débito",F25="Crédito",F25="Internet(Shopify)"),E25*19/119,0) -> 0 | H25: =IF(F25="Débito",0.0275,IF(F25="Crédito",0.0295,0)) -> 0 | I25: =E25*H25 -> 0 | J25: =E25-G25-I25 -> 30000 | K25: =IF($O25<>"Tienda",0,IF(OR($F25="Débito",$F25="Crédito"),0.05,IF(OR($F25="Efectivo",$F25="Transferencia"),0.07,0))) -> 0.07 | L25: =IF($O25<>"Tienda",0,$J25*$K25) -> 2100 | M25: =E25-G25-I25-L25 -> 27900 | O25: Tienda
A26: Blaizer Maison Margiela | C26: Tienda | D26: Aaron | E26: 250000 | F26: Transferencia | G26: =IF(OR(F26="Débito",F26="Crédito",F26="Internet(Shopify)"),E26*19/119,0) -> 0 | H26: =IF(F26="Débito",0.0275,IF(F26="Crédito",0.0295,0)) -> 0 | I26: =E26*H26 -> 0 | J26: =E26-G26-I26 -> 250000 | K26: =IF($O26<>"Tienda",0,IF(OR($F26="Débito",$F26="Crédito"),0.05,IF(OR($F26="Efectivo",$F26="Transferencia"),0.07,0))) -> 0.07 | L26: =IF($O26<>"Tienda",0,$J26*$K26) -> 17500 | M26: =E26-G26-I26-L26 -> 232500 | O26: Tienda
A27: Poleron Encaje S.Archive | B27: s | C27: Tienda | D27: Marenna | E27: 60000 | F27: Transferencia | G27: =IF(OR(F27="Débito",F27="Crédito",F27="Internet(Shopify)"),E27*19/119,0) -> 0 | H27: =IF(F27="Débito",0.0275,IF(F27="Crédito",0.0295,0)) -> 0 | I27: =E27*H27 -> 0 | J27: =E27-G27-I27 -> 60000 | K27: =IF($O27<>"Tienda",0,IF(OR($F27="Débito",$F27="Crédito"),0.05,IF(OR($F27="Efectivo",$F27="Transferencia"),0.07,0))) -> 0 | L27: =IF($O27<>"Tienda",0,$J27*$K27) -> 0 | M27: =E27-G27-I27-L27 -> 60000 | N27: Season Archive 45.000 | O27: Season Archive
A28: Pusera Fabinho | B28: os | C28: Fabio | D28: Marenna | E28: 25000 | F28: Transferencia | G28: =IF(OR(F28="Débito",F28="Crédito",F28="Internet(Shopify)"),E28*19/119,0) -> 0 | H28: =IF(F28="Débito",0.0275,IF(F28="Crédito",0.0295,0)) -> 0 | I28: =E28*H28 -> 0 | J28: =E28-G28-I28 -> 25000 | K28: =IF($O28<>"Tienda",0,IF(OR($F28="Débito",$F28="Crédito"),0.05,IF(OR($F28="Efectivo",$F28="Transferencia"),0.07,0))) -> 0.07 | L28: =IF($O28<>"Tienda",0,$J28*$K28) -> 1750 | M28: =E28-G28-I28-L28 -> 23250 | O28: Tienda
A29: Lentes Chanel | C29: Benja R | D29: Marenna | E29: 110000 | F29: Transferencia | G29: =IF(OR(F29="Débito",F29="Crédito",F29="Internet(Shopify)"),E29*19/119,0) -> 0 | H29: =IF(F29="Débito",0.0275,IF(F29="Crédito",0.0295,0)) -> 0 | I29: =E29*H29 -> 0 | J29: =E29-G29-I29 -> 110000 | K29: =IF($O29<>"Tienda",0,IF(OR($F29="Débito",$F29="Crédito"),0.05,IF(OR($F29="Efectivo",$F29="Transferencia"),0.07,0))) -> 0.07 | L29: =IF($O29<>"Tienda",0,$J29*$K29) -> 7700 | M29: =E29-G29-I29-L29 -> 102300 | O29: Tienda
A30: Bufanda P. Disaster | C30: Tienda | D30: Marenna | E30: 20000 | F30: Transferencia | G30: =IF(OR(F30="Débito",F30="Crédito",F30="Internet(Shopify)"),E30*19/119,0) -> 0 | H30: =IF(F30="Débito",0.0275,IF(F30="Crédito",0.0295,0)) -> 0 | I30: =E30*H30 -> 0 | J30: =E30-G30-I30 -> 20000 | K30: =IF($O30<>"Tienda",0,IF(OR($F30="Débito",$F30="Crédito"),0.05,IF(OR($F30="Efectivo",$F30="Transferencia"),0.07,0))) -> 0 | L30: =IF($O30<>"Tienda",0,$J30*$K30) -> 0 | M30: =E30-G30-I30-L30 -> 20000 | N30: Pop Disaster 15.000 | O30: Pop disaster
A31: Billetera Lv | C31: Tienda | D31: Marenna | E31: 40000 | F31: Transferencia | G31: =IF(OR(F31="Débito",F31="Crédito",F31="Internet(Shopify)"),E31*19/119,0) -> 0 | H31: =IF(F31="Débito",0.0275,IF(F31="Crédito",0.0295,0)) -> 0 | I31: =E31*H31 -> 0 | J31: =E31-G31-I31 -> 40000 | K31: =IF($O31<>"Tienda",0,IF(OR($F31="Débito",$F31="Crédito"),0.05,IF(OR($F31="Efectivo",$F31="Transferencia"),0.07,0))) -> 0 | L31: =IF($O31<>"Tienda",0,$J31*$K31) -> 0 | M31: =E31-G31-I31-L31 -> 40000
G32: =IF(OR(F32="Débito",F32="Crédito",F32="Internet(Shopify)"),E32*19/119,0) -> 0 | H32: =IF(F32="Débito",0.0275,IF(F32="Crédito",0.0295,0)) -> 0 | I32: =E32*H32 -> 0 | J32: =E32-G32-I32 -> 0 | K32: =IF($O32<>"Tienda",0,IF(OR($F32="Débito",$F32="Crédito"),0.05,IF(OR($F32="Efectivo",$F32="Transferencia"),0.07,0))) -> 0 | L32: =IF($O32<>"Tienda",0,$J32*$K32) -> 0 | M32: =E32-G32-I32-L32 -> 0
G33: =IF(OR(F33="Débito",F33="Crédito",F33="Internet(Shopify)"),E33*19/119,0) -> 0 | H33: =IF(F33="Débito",0.0275,IF(F33="Crédito",0.0295,0)) -> 0 | I33: =E33*H33 -> 0 | J33: =E33-G33-I33 -> 0 | K33: =IF($O33<>"Tienda",0,IF(OR($F33="Débito",$F33="Crédito"),0.05,IF(OR($F33="Efectivo",$F33="Transferencia"),0.07,0))) -> 0 | L33: =IF($O33<>"Tienda",0,$J33*$K33) -> 0 | M33: =E33-G33-I33-L33 -> 0
G34: =IF(OR(F34="Débito",F34="Crédito",F34="Internet(Shopify)"),E34*19/119,0) -> 0 | H34: =IF(F34="Débito",0.0275,IF(F34="Crédito",0.0295,0)) -> 0 | I34: =E34*H34 -> 0 | J34: =E34-G34-I34 -> 0 | K34: =IF($O34<>"Tienda",0,IF(OR($F34="Débito",$F34="Crédito"),0.05,IF(OR($F34="Efectivo",$F34="Transferencia"),0.07,0))) -> 0 | L34: =IF($O34<>"Tienda",0,$J34*$K34) -> 0 | M34: =E34-G34-I34-L34 -> 0
G35: =IF(OR(F35="Débito",F35="Crédito",F35="Internet(Shopify)"),E35*19/119,0) -> 0 | H35: =IF(F35="Débito",0.0275,IF(F35="Crédito",0.0295,0)) -> 0 | I35: =E35*H35 -> 0 | J35: =E35-G35-I35 -> 0 | K35: =IF($O35<>"Tienda",0,IF(OR($F35="Débito",$F35="Crédito"),0.05,IF(OR($F35="Efectivo",$F35="Transferencia"),0.07,0))) -> 0 | L35: =IF($O35<>"Tienda",0,$J35*$K35) -> 0 | M35: =E35-G35-I35-L35 -> 0
G36: =IF(OR(F36="Débito",F36="Crédito",F36="Internet(Shopify)"),E36*19/119,0) -> 0 | H36: =IF(F36="Débito",0.0275,IF(F36="Crédito",0.0295,0)) -> 0 | I36: =E36*H36 -> 0 | J36: =E36-G36-I36 -> 0 | K36: =IF($O36<>"Tienda",0,IF(OR($F36="Débito",$F36="Crédito"),0.05,IF(OR($F36="Efectivo",$F36="Transferencia"),0.07,0))) -> 0 | L36: =IF($O36<>"Tienda",0,$J36*$K36) -> 0 | M36: =E36-G36-I36-L36 -> 0
G37: =IF(OR(F37="Débito",F37="Crédito",F37="Internet(Shopify)"),E37*19/119,0) -> 0 | H37: =IF(F37="Débito",0.0275,IF(F37="Crédito",0.0295,0)) -> 0 | I37: =E37*H37 -> 0 | J37: =E37-G37-I37 -> 0 | K37: =IF($O37<>"Tienda",0,IF(OR($F37="Débito",$F37="Crédito"),0.05,IF(OR($F37="Efectivo",$F37="Transferencia"),0.07,0))) -> 0 | L37: =IF($O37<>"Tienda",0,$J37*$K37) -> 0 | M37: =E37-G37-I37-L37 -> 0
G38: =IF(OR(F38="Débito",F38="Crédito",F38="Internet(Shopify)"),E38*19/119,0) -> 0 | H38: =IF(F38="Débito",0.0275,IF(F38="Crédito",0.0295,0)) -> 0 | I38: =E38*H38 -> 0 | J38: =E38-G38-I38 -> 0 | K38: =IF($O38<>"Tienda",0,IF(OR($F38="Débito",$F38="Crédito"),0.05,IF(OR($F38="Efectivo",$F38="Transferencia"),0.07,0))) -> 0 | L38: =IF($O38<>"Tienda",0,$J38*$K38) -> 0 | M38: =E38-G38-I38-L38 -> 0
G39: =IF(OR(F39="Débito",F39="Crédito",F39="Internet(Shopify)"),E39*19/119,0) -> 0 | H39: =IF(F39="Débito",0.0275,IF(F39="Crédito",0.0295,0)) -> 0 | I39: =E39*H39 -> 0 | J39: =E39-G39-I39 -> 0 | K39: =IF($O39<>"Tienda",0,IF(OR($F39="Débito",$F39="Crédito"),0.05,IF(OR($F39="Efectivo",$F39="Transferencia"),0.07,0))) -> 0 | L39: =IF($O39<>"Tienda",0,$J39*$K39) -> 0 | M39: =E39-G39-I39-L39 -> 0
G40: =IF(OR(F40="Débito",F40="Crédito",F40="Internet(Shopify)"),E40*19/119,0) -> 0 | H40: =IF(F40="Débito",0.0275,IF(F40="Crédito",0.0295,0)) -> 0 | I40: =E40*H40 -> 0 | J40: =E40-G40-I40 -> 0 | K40: =IF($O40<>"Tienda",0,IF(OR($F40="Débito",$F40="Crédito"),0.05,IF(OR($F40="Efectivo",$F40="Transferencia"),0.07,0))) -> 0 | L40: =IF($O40<>"Tienda",0,$J40*$K40) -> 0 | M40: =E40-G40-I40-L40 -> 0
...

Sheet Abril
A1: Abril - Ingresos
P2: Total ventas brutas | Q2: =SUM(E4:E103) -> 3919000
A3: Nombre prenda | B3: Talla | C3: Propietario prenda | D3: Vendedor | E3: Precio venta (BRUTO) | F3: Tipo de pago | G3: IVA (19%) | H3: % comisión bancaria | I3: $ comisión bancaria | J3: Base comisión vendedor | K3: % comisión vendedor | L3: $ comisión vendedor | M3: Neto tienda | N3: Observaciones | O3: Marca (Tienda/externa) | P3: Total IVA ventas | Q3: =SUM(G4:G103) -> 47899.16
A4: POLERON ESSENTIAL ROSADO | B4: - | C4: Tienda | D4: Aaron | E4: 80000 | F4: Crédito | G4: =IF(OR(F4="Débito",F4="Crédito",F4="Internet(Shopify)"),E4*19/119,0) -> 12773.109 | H4: =IF(F4="Débito",0.0275,IF(F4="Crédito",0.0295,0)) -> 0.0295 | I4: =E4*H4 -> 2360 | J4: =E4-G4-I4 -> 64866.891 | K4: =IF($O4<>"Tienda",0,IF(OR($F4="Débito",$F4="Crédito"),0.05,IF(OR($F4="Efectivo",$F4="Transferencia"),0.07,0))) -> 0 | L4: =IF($O4<>"Tienda",0,$J4*$K4) -> 0 | M4: =E4-G4-I4-L4 -> 64866.891 | N4: VENTA EXENTA IVA | P4: Total comisiones bancarias | Q4: =SUM(I4:I103) -> 8650
A5: anillo onyx | B5: - | C5: Tienda | D5: Aaron | E5: 50000 | F5: Transferencia | G5: =IF(OR(F5="Débito",F5="Crédito",F5="Internet(Shopify)"),E5*19/119,0) -> 0 | H5: =IF(F5="Débito",0.0275,IF(F5="Crédito",0.0295,0)) -> 0 | I5: =E5*H5 -> 0 | J5: =E5-G5-I5 -> 50000 | K5: =IF($O5<>"Tienda",0,IF(OR($F5="Débito",$F5="Crédito"),0.05,IF(OR($F5="Efectivo",$F5="Transferencia"),0.07,0))) -> 0 | L5: =IF($O5<>"Tienda",0,$J5*$K5) -> 0 | M5: =E5-G5-I5-L5 -> 50000 | N5: Artista anillo ($37.500) | P5: Total comisiones vendedores (NO se divide) | Q5: =SUM(L4:L103) -> 218999.2
A6: anillo simple | B6: - | C6: Tienda | D6: Aaron | E6: 30000 | F6: Transferencia | G6: =IF(OR(F6="Débito",F6="Crédito",F6="Internet(Shopify)"),E6*19/119,0) -> 0 | H6: =IF(F6="Débito",0.0275,IF(F6="Crédito",0.0295,0)) -> 0 | I6: =E6*H6 -> 0 | J6: =E6-G6-I6 -> 30000 | K6: =IF($O6<>"Tienda",0,IF(OR($F6="Débito",$F6="Crédito"),0.05,IF(OR($F6="Efectivo",$F6="Transferencia"),0.07,0))) -> 0 | L6: =IF($O6<>"Tienda",0,$J6*$K6) -> 0 | M6: =E6-G6-I6-L6 -> 30000 | N6: Artista anillo ($22.500) | P6: Total neto tienda (NO se divide) | Q6: =SUM(M4:M103) -> 3643451.6
A7: poleron burberry | B7: L | C7: Fabio | D7: Marenna | E7: 35000 | F7: Transferencia | G7: =IF(OR(F7="Débito",F7="Crédito",F7="Internet(Shopify)"),E7*19/119,0) -> 0 | H7: =IF(F7="Débito",0.0275,IF(F7="Crédito",0.0295,0)) -> 0 | I7: =E7*H7 -> 0 | J7: =E7-G7-I7 -> 35000 | K7: =IF($O7<>"Tienda",0,IF(OR($F7="Débito",$F7="Crédito"),0.05,IF(OR($F7="Efectivo",$F7="Transferencia"),0.07,0))) -> 0.07 | L7: =IF($O7<>"Tienda",0,$J7*$K7) -> 2450 | M7: =E7-G7-I7-L7 -> 32550 | O7: Tienda | P7: Número de ventas | Q7: =COUNTA(E4:E103) -> 55
A8: Lentes Fendi | C8: Fabio | D8: Marenna | E8: 100000 | F8: Transferencia | G8: =IF(OR(F8="Débito",F8="Crédito",F8="Internet(Shopify)"),E8*19/119,0) -> 0 | H8: =IF(F8="Débito",0.0275,IF(F8="Crédito",0.0295,0)) -> 0 | I8: =E8*H8 -> 0 | J8: =E8-G8-I8 -> 100000 | K8: =IF($O8<>"Tienda",0,IF(OR($F8="Débito",$F8="Crédito"),0.05,IF(OR($F8="Efectivo",$F8="Transferencia"),0.07,0))) -> 0.07 | L8: =IF($O8<>"Tienda",0,$J8*$K8) -> 7000 | M8: =E8-G8-I8-L8 -> 93000 | O8: Tienda | P8: Ticket promedio (NETO) | Q8: =IF(Q7=0,0,Q6/Q7) -> 66244.575
A9: Cartera Burberry | C9: Tienda | D9: Marenna | E9: 60000 | F9: Transferencia | G9: =IF(OR(F9="Débito",F9="Crédito",F9="Internet(Shopify)"),E9*19/119,0) -> 0 | H9: =IF(F9="Débito",0.0275,IF(F9="Crédito",0.0295,0)) -> 0 | I9: =E9*H9 -> 0 | J9: =E9-G9-I9 -> 60000 | K9: =IF($O9<>"Tienda",0,IF(OR($F9="Débito",$F9="Crédito"),0.05,IF(OR($F9="Efectivo",$F9="Transferencia"),0.07,0))) -> 0.07 | L9: =IF($O9<>"Tienda",0,$J9*$K9) -> 4200 | M9: =E9-G9-I9-L9 -> 55800 | O9: Tienda | P9: Ventas débito (neto) | Q9: =SUMIF(F4:F103,"Débito",M4:M103) -> 77219.433
A10: Falda Diesel | B10: 34 | G10: =IF(OR(F10="Débito",F10="Crédito",F10="Internet(Shopify)"),E10*19/119,0) -> 0 | H10: =IF(F10="Débito",0.0275,IF(F10="Crédito",0.0295,0)) -> 0 | I10: =E10*H10 -> 0 | J10: =E10-G10-I10 -> 0 | K10: =IF($O10<>"Tienda",0,IF(OR($F10="Débito",$F10="Crédito"),0.05,IF(OR($F10="Efectivo",$F10="Transferencia"),0.07,0))) -> 0 | L10: =IF($O10<>"Tienda",0,$J10*$K10) -> 0 | M10: =E10-G10-I10-L10 -> 0 | P10: Ventas crédito (neto) | Q10: =SUMIF(F4:F103,"Crédito",M4:M103) -> 157302.21
A11: Falda Diesel | B11: 34 | C11: Benja R | D11: Marenna | E11: 20000 | F11: Transferencia | G11: =IF(OR(F11="Débito",F11="Crédito",F11="Internet(Shopify)"),E11*19/119,0) -> 0 | H11: =IF(F11="Débito",0.0275,IF(F11="Crédito",0.0295,0)) -> 0 | I11: =E11*H11 -> 0 | J11: =E11-G11-I11 -> 20000 | K11: =IF($O11<>"Tienda",0,IF(OR($F11="Débito",$F11="Crédito"),0.05,IF(OR($F11="Efectivo",$F11="Transferencia"),0.07,0))) -> 0.07 | L11: =IF($O11<>"Tienda",0,$J11*$K11) -> 1400 | M11: =E11-G11-I11-L11 -> 18600 | N11: pagar michelle 20.000 | O11: Tienda | P11: Ventas efectivo (neto) | Q11: =SUMIF(F4:F103,"Efectivo",M4:M103) -> 111600
A12: vest raro | B12: os | C12: Fabio | D12: Marenna | E12: 35000 | F12: Transferencia | G12: =IF(OR(F12="Débito",F12="Crédito",F12="Internet(Shopify)"),E12*19/119,0) -> 0 | H12: =IF(F12="Débito",0.0275,IF(F12="Crédito",0.0295,0)) -> 0 | I12: =E12*H12 -> 0 | J12: =E12-G12-I12 -> 35000 | K12: =IF($O12<>"Tienda",0,IF(OR($F12="Débito",$F12="Crédito"),0.05,IF(OR($F12="Efectivo",$F12="Transferencia"),0.07,0))) -> 0.07 | L12: =IF($O12<>"Tienda",0,$J12*$K12) -> 2450 | M12: =E12-G12-I12-L12 -> 32550 | O12: Tienda | P12: Ventas transferencia (neto) | Q12: =SUMIF(F4:F103,"Transferencia",M4:M103) -> 3297330
A13: polera heron | B13: os | C13: Benja R | D13: Marenna | E13: 8000 | F13: Transferencia | G13: =IF(OR(F13="Débito",F13="Crédito",F13="Internet(Shopify)"),E13*19/119,0) -> 0 | H13: =IF(F13="Débito",0.0275,IF(F13="Crédito",0.0295,0)) -> 0 | I13: =E13*H13 -> 0 | J13: =E13-G13-I13 -> 8000 | K13: =IF($O13<>"Tienda",0,IF(OR($F13="Débito",$F13="Crédito"),0.05,IF(OR($F13="Efectivo",$F13="Transferencia"),0.07,0))) -> 0.07 | L13: =IF($O13<>"Tienda",0,$J13*$K13) -> 560 | M13: =E13-G13-I13-L13 -> 7440 | O13: Tienda | P13: Ventas Internet(Shopify) (neto) | Q13: =SUMIF(F4:F103,"Internet(Shopify)",M4:M103) -> 0
A14: polera stussy | B14: m | C14: Aaron | D14: Benja R | E14: 30000 | F14: Transferencia | G14: =IF(OR(F14="Débito",F14="Crédito",F14="Internet(Shopify)"),E14*19/119,0) -> 0 | H14: =IF(F14="Débito",0.0275,IF(F14="Crédito",0.0295,0)) -> 0 | I14: =E14*H14 -> 0 | J14: =E14-G14-I14 -> 30000 | K14: =IF($O14<>"Tienda",0,IF(OR($F14="Débito",$F14="Crédito"),0.05,IF(OR($F14="Efectivo",$F14="Transferencia"),0.07,0))) -> 0 | L14: =IF($O14<>"Tienda",0,$J14*$K14) -> 0 | M14: =E14-G14-I14-L14 -> 30000 | N14: mivhelle | P14: Ventas cuenta común (D+C+T) NETO | Q14: =SUMIF(F4:F103,"Débito",M4:M103)+SUMIF(F4:F103,"Crédito",M4:M103)+SUMIF(F4:F103,"Transferencia",M4:M103) -> 3531851.6
A15: polera ed hardy | B15: s | C15: Benja R | D15: Benja R | E15: 13000 | F15: Transferencia | G15: =IF(OR(F15="Débito",F15="Crédito",F15="Internet(Shopify)"),E15*19/119,0) -> 0 | H15: =IF(F15="Débito",0.0275,IF(F15="Crédito",0.0295,0)) -> 0 | I15: =E15*H15 -> 0 | J15: =E15-G15-I15 -> 13000 | K15: =IF($O15<>"Tienda",0,IF(OR($F15="Débito",$F15="Crédito"),0.05,IF(OR($F15="Efectivo",$F15="Transferencia"),0.07,0))) -> 0 | L15: =IF($O15<>"Tienda",0,$J15*$K15) -> 0 | M15: =E15-G15-I15-L15 -> 13000 | N15: michelle | P15: IVA compras (manual)
A16: 3 poleras vintage benja | C16: Benja R | D16: Fabio | E16: 30000 | F16: Transferencia | G16: =IF(OR(F16="Débito",F16="Crédito",F16="Internet(Shopify)"),E16*19/119,0) -> 0 | H16: =IF(F16="Débito",0.0275,IF(F16="Crédito",0.0295,0)) -> 0 | I16: =E16*H16 -> 0 | J16: =E16-G16-I16 -> 30000 | K16: =IF($O16<>"Tienda",0,IF(OR($F16="Débito",$F16="Crédito"),0.05,IF(OR($F16="Efectivo",$F16="Transferencia"),0.07,0))) -> 0.07 | L16: =IF($O16<>"Tienda",0,$J16*$K16) -> 2100 | M16: =E16-G16-I16-L16 -> 27900 | O16: Tienda | P16: IVA neto (ventas - compras) | Q16: =Q3-Q15 -> 47899.16
A17: Polera IQ | C17: Consignacion | D17: Fabio | E17: 30000 | F17: Transferencia | G17: =IF(OR(F17="Débito",F17="Crédito",F17="Internet(Shopify)"),E17*19/119,0) -> 0 | H17: =IF(F17="Débito",0.0275,IF(F17="Crédito",0.0295,0)) -> 0 | I17: =E17*H17 -> 0 | J17: =E17-G17-I17 -> 30000 | K17: =IF($O17<>"Tienda",0,IF(OR($F17="Débito",$F17="Crédito"),0.05,IF(OR($F17="Efectivo",$F17="Transferencia"),0.07,0))) -> 0 | L17: =IF($O17<>"Tienda",0,$J17*$K17) -> 0 | M17: =E17-G17-I17-L17 -> 30000 | N17: Gelattos (22.500) | O17: Gelattos | P17: INGRESOS 05 DE C/MES | Q17: =SUM(E4:E26) -> 959000
A18: Moto con fuego mangalarga | C18: Aaron | D18: Marenna | E18: 15000 | F18: Transferencia | G18: =IF(OR(F18="Débito",F18="Crédito",F18="Internet(Shopify)"),E18*19/119,0) -> 0 | H18: =IF(F18="Débito",0.0275,IF(F18="Crédito",0.0295,0)) -> 0 | I18: =E18*H18 -> 0 | J18: =E18-G18-I18 -> 15000 | K18: =IF($O18<>"Tienda",0,IF(OR($F18="Débito",$F18="Crédito"),0.05,IF(OR($F18="Efectivo",$F18="Transferencia"),0.07,0))) -> 0.07 | L18: =IF($O18<>"Tienda",0,$J18*$K18) -> 1050 | M18: =E18-G18-I18-L18 -> 13950 | O18: Tienda | P18: INGRESO REAL DE ESTE MES | Q18: =SUM(E27:E560) -> 2960000
A19: Polera Acne marca en cuello | C19: Aaron | D19: Marenna | E19: 40000 | F19: Transferencia | G19: =IF(OR(F19="Débito",F19="Crédito",F19="Internet(Shopify)"),E19*19/119,0) -> 0 | H19: =IF(F19="Débito",0.0275,IF(F19="Crédito",0.0295,0)) -> 0 | I19: =E19*H19 -> 0 | J19: =E19-G19-I19 -> 40000 | K19: =IF($O19<>"Tienda",0,IF(OR($F19="Débito",$F19="Crédito"),0.05,IF(OR($F19="Efectivo",$F19="Transferencia"),0.07,0))) -> 0.07 | L19: =IF($O19<>"Tienda",0,$J19*$K19) -> 2800 | M19: =E19-G19-I19-L19 -> 37200 | O19: Tienda
A20: Polera Supreme | B20: m | C20: Aaron | D20: Benja R | E20: 20000 | F20: Transferencia | G20: =IF(OR(F20="Débito",F20="Crédito",F20="Internet(Shopify)"),E20*19/119,0) -> 0 | H20: =IF(F20="Débito",0.0275,IF(F20="Crédito",0.0295,0)) -> 0 | I20: =E20*H20 -> 0 | J20: =E20-G20-I20 -> 20000 | K20: =IF($O20<>"Tienda",0,IF(OR($F20="Débito",$F20="Crédito"),0.05,IF(OR($F20="Efectivo",$F20="Transferencia"),0.07,0))) -> 0.07 | L20: =IF($O20<>"Tienda",0,$J20*$K20) -> 1400 | M20: =E20-G20-I20-L20 -> 18600 | N20: michelle | O20: Tienda
A21: Polera Stussy | B21: m | C21: Benja R | D21: Marenna | E21: 28000 | F21: Transferencia | G21: =IF(OR(F21="Débito",F21="Crédito",F21="Internet(Shopify)"),E21*19/119,0) -> 0 | H21: =IF(F21="Débito",0.0275,IF(F21="Crédito",0.0295,0)) -> 0 | I21: =E21*H21 -> 0 | J21: =E21-G21-I21 -> 28000 | K21: =IF($O21<>"Tienda",0,IF(OR($F21="Débito",$F21="Crédito"),0.05,IF(OR($F21="Efectivo",$F21="Transferencia"),0.07,0))) -> 0.07 | L21: =IF($O21<>"Tienda",0,$J21*$K21) -> 1960 | M21: =E21-G21-I21-L21 -> 26040 | O21: Tienda
A22: Zapato Jeffery West | B22: 43 | C22: Consignacion | D22: Fabio | E22: 180000 | F22: Transferencia | G22: =IF(OR(F22="Débito",F22="Crédito",F22="Internet(Shopify)"),E22*19/119,0) -> 0 | H22: =IF(F22="Débito",0.0275,IF(F22="Crédito",0.0295,0)) -> 0 | I22: =E22*H22 -> 0 | J22: =E22-G22-I22 -> 180000 | K22: =IF($O22<>"Tienda",0,IF(OR($F22="Débito",$F22="Crédito"),0.05,IF(OR($F22="Efectivo",$F22="Transferencia"),0.07,0))) -> 0.07 | L22: =IF($O22<>"Tienda",0,$J22*$K22) -> 12600 | M22: =E22-G22-I22-L22 -> 167400 | N22: Federico( | O22: Tienda
A23: Polera futbol adidas | B23: l | C23: Fabio | D23: Marenna | E23: 35000 | F23: Transferencia | G23: =IF(OR(F23="Débito",F23="Crédito",F23="Internet(Shopify)"),E23*19/119,0) -> 0 | H23: =IF(F23="Débito",0.0275,IF(F23="Crédito",0.0295,0)) -> 0 | I23: =E23*H23 -> 0 | J23: =E23-G23-I23 -> 35000 | K23: =IF($O23<>"Tienda",0,IF(OR($F23="Débito",$F23="Crédito"),0.05,IF(OR($F23="Efectivo",$F23="Transferencia"),0.07,0))) -> 0.07 | L23: =IF($O23<>"Tienda",0,$J23*$K23) -> 2450 | M23: =E23-G23-I23-L23 -> 32550 | O23: Tienda
A24: Sudadera JPG Jeans Flecos | B24: m | C24: Tienda | D24: Marenna | E24: 55000 | F24: Transferencia | G24: =IF(OR(F24="Débito",F24="Crédito",F24="Internet(Shopify)"),E24*19/119,0) -> 0 | H24: =IF(F24="Débito",0.0275,IF(F24="Crédito",0.0295,0)) -> 0 | I24: =E24*H24 -> 0 | J24: =E24-G24-I24 -> 55000 | K24: =IF($O24<>"Tienda",0,IF(OR($F24="Débito",$F24="Crédito"),0.05,IF(OR($F24="Efectivo",$F24="Transferencia"),0.07,0))) -> 0.07 | L24: =IF($O24<>"Tienda",0,$J24*$K24) -> 3850 | M24: =E24-G24-I24-L24 -> 51150 | O24: Tienda
A25: Poleron Sandro | B25: m | C25: Tienda | D25: Fabio | E25: 25000 | F25: Transferencia | G25: =IF(OR(F25="Débito",F25="Crédito",F25="Internet(Shopify)"),E25*19/119,0) -> 0 | H25: =IF(F25="Débito",0.0275,IF(F25="Crédito",0.0295,0)) -> 0 | I25: =E25*H25 -> 0 | J25: =E25-G25-I25 -> 25000 | K25: =IF($O25<>"Tienda",0,IF(OR($F25="Débito",$F25="Crédito"),0.05,IF(OR($F25="Efectivo",$F25="Transferencia"),0.07,0))) -> 0.07 | L25: =IF($O25<>"Tienda",0,$J25*$K25) -> 1750 | M25: =E25-G25-I25-L25 -> 23250 | O25: Tienda
A26: Short Dolce* | B26: M | C26: Aaron | D26: Fabio | E26: 40000 | F26: Transferencia | G26: =IF(OR(F26="Débito",F26="Crédito",F26="Internet(Shopify)"),E26*19/119,0) -> 0 | H26: =IF(F26="Débito",0.0275,IF(F26="Crédito",0.0295,0)) -> 0 | I26: =E26*H26 -> 0 | J26: =E26-G26-I26 -> 40000 | K26: =IF($O26<>"Tienda",0,IF(OR($F26="Débito",$F26="Crédito"),0.05,IF(OR($F26="Efectivo",$F26="Transferencia"),0.07,0))) -> 0.07 | L26: =IF($O26<>"Tienda",0,$J26*$K26) -> 2800 | M26: =E26-G26-I26-L26 -> 37200 | O26: Tienda
A27: polera supreme big logo | B27: L | C27: Aaron | D27: Benja R | E27: 35000 | F27: Transferencia | G27: =IF(OR(F27="Débito",F27="Crédito",F27="Internet(Shopify)"),E27*19/119,0) -> 0 | H27: =IF(F27="Débito",0.0275,IF(F27="Crédito",0.0295,0)) -> 0 | I27: =E27*H27 -> 0 | J27: =E27-G27-I27 -> 35000 | K27: =IF($O27<>"Tienda",0,IF(OR($F27="Débito",$F27="Crédito"),0.05,IF(OR($F27="Efectivo",$F27="Transferencia"),0.07,0))) -> 0.07 | L27: =IF($O27<>"Tienda",0,$J27*$K27) -> 2450 | M27: =E27-G27-I27-L27 -> 32550 | O27: Tienda
A28: polerA OFF WHITE | B28: L | C28: Tienda | D28: Benja R | E28: 40000 | F28: Transferencia | G28: =IF(OR(F28="Débito",F28="Crédito",F28="Internet(Shopify)"),E28*19/119,0) -> 0 | H28: =IF(F28="Débito",0.0275,IF(F28="Crédito",0.0295,0)) -> 0 | I28: =E28*H28 -> 0 | J28: =E28-G28-I28 -> 40000 | K28: =IF($O28<>"Tienda",0,IF(OR($F28="Débito",$F28="Crédito"),0.05,IF(OR($F28="Efectivo",$F28="Transferencia"),0.07,0))) -> 0.07 | L28: =IF($O28<>"Tienda",0,$J28*$K28) -> 2800 | M28: =E28-G28-I28-L28 -> 37200 | O28: Tienda
A29: aros fab | B29: op | C29: Fabio | D29: Fabio | E29: 20000 | F29: Transferencia | G29: =IF(OR(F29="Débito",F29="Crédito",F29="Internet(Shopify)"),E29*19/119,0) -> 0 | H29: =IF(F29="Débito",0.0275,IF(F29="Crédito",0.0295,0)) -> 0 | I29: =E29*H29 -> 0 | J29: =E29-G29-I29 -> 20000 | K29: =IF($O29<>"Tienda",0,IF(OR($F29="Débito",$F29="Crédito"),0.05,IF(OR($F29="Efectivo",$F29="Transferencia"),0.07,0))) -> 0.07 | L29: =IF($O29<>"Tienda",0,$J29*$K29) -> 1400 | M29: =E29-G29-I29-L29 -> 18600 | O29: Tienda
A30: hoodie Helmut Blanco | B30: M | C30: Aaron | D30: Fabio | E30: 70000 | F30: Transferencia | G30: =IF(OR(F30="Débito",F30="Crédito",F30="Internet(Shopify)"),E30*19/119,0) -> 0 | H30: =IF(F30="Débito",0.0275,IF(F30="Crédito",0.0295,0)) -> 0 | I30: =E30*H30 -> 0 | J30: =E30-G30-I30 -> 70000 | K30: =IF($O30<>"Tienda",0,IF(OR($F30="Débito",$F30="Crédito"),0.05,IF(OR($F30="Efectivo",$F30="Transferencia"),0.07,0))) -> 0.07 | L30: =IF($O30<>"Tienda",0,$J30*$K30) -> 4900 | M30: =E30-G30-I30-L30 -> 65100 | O30: Tienda
A31: Polera Hiddien | B31: l | C31: Fabio | D31: Fabio | E31: 45000 | F31: Transferencia | G31: =IF(OR(F31="Débito",F31="Crédito",F31="Internet(Shopify)"),E31*19/119,0) -> 0 | H31: =IF(F31="Débito",0.0275,IF(F31="Crédito",0.0295,0)) -> 0 | I31: =E31*H31 -> 0 | J31: =E31-G31-I31 -> 45000 | K31: =IF($O31<>"Tienda",0,IF(OR($F31="Débito",$F31="Crédito"),0.05,IF(OR($F31="Efectivo",$F31="Transferencia"),0.07,0))) -> 0.07 | L31: =IF($O31<>"Tienda",0,$J31*$K31) -> 3150 | M31: =E31-G31-I31-L31 -> 41850 | O31: Tienda
A32: vest jil sander | B32: s | C32: Aaron | D32: Fabio | E32: 75000 | F32: Transferencia | G32: =IF(OR(F32="Débito",F32="Crédito",F32="Internet(Shopify)"),E32*19/119,0) -> 0 | H32: =IF(F32="Débito",0.0275,IF(F32="Crédito",0.0295,0)) -> 0 | I32: =E32*H32 -> 0 | J32: =E32-G32-I32 -> 75000 | K32: =IF($O32<>"Tienda",0,IF(OR($F32="Débito",$F32="Crédito"),0.05,IF(OR($F32="Efectivo",$F32="Transferencia"),0.07,0))) -> 0.07 | L32: =IF($O32<>"Tienda",0,$J32*$K32) -> 5250 | M32: =E32-G32-I32-L32 -> 69750 | O32: Tienda
A33: gorro NY | B33: Unica | C33: Fabio | D33: Benja R | E33: 25000 | F33: Transferencia | G33: =IF(OR(F33="Débito",F33="Crédito",F33="Internet(Shopify)"),E33*19/119,0) -> 0 | H33: =IF(F33="Débito",0.0275,IF(F33="Crédito",0.0295,0)) -> 0 | I33: =E33*H33 -> 0 | J33: =E33-G33-I33 -> 25000 | K33: =IF($O33<>"Tienda",0,IF(OR($F33="Débito",$F33="Crédito"),0.05,IF(OR($F33="Efectivo",$F33="Transferencia"),0.07,0))) -> 0.07 | L33: =IF($O33<>"Tienda",0,$J33*$K33) -> 1750 | M33: =E33-G33-I33-L33 -> 23250 | N33: MICHELLE | O33: Tienda
A34: polera APPE | B34: L | C34: Benja R | D34: Benja R | E34: 25000 | F34: Transferencia | G34: =IF(OR(F34="Débito",F34="Crédito",F34="Internet(Shopify)"),E34*19/119,0) -> 0 | H34: =IF(F34="Débito",0.0275,IF(F34="Crédito",0.0295,0)) -> 0 | I34: =E34*H34 -> 0 | J34: =E34-G34-I34 -> 25000 | K34: =IF($O34<>"Tienda",0,IF(OR($F34="Débito",$F34="Crédito"),0.05,IF(OR($F34="Efectivo",$F34="Transferencia"),0.07,0))) -> 0.07 | L34: =IF($O34<>"Tienda",0,$J34*$K34) -> 1750 | M34: =E34-G34-I34-L34 -> 23250 | N34: michelle | O34: Tienda
A35: polera phillip plein | B35: XS | C35: Benja R | D35: Benja R | E35: 25000 | F35: Débito | G35: =IF(OR(F35="Débito",F35="Crédito",F35="Internet(Shopify)"),E35*19/119,0) -> 3991.5966 | H35: =IF(F35="Débito",0.0275,IF(F35="Crédito",0.0295,0)) -> 0.0275 | I35: =E35*H35 -> 687.5 | J35: =E35-G35-I35 -> 20320.903 | K35: =IF($O35<>"Tienda",0,IF(OR($F35="Débito",$F35="Crédito"),0.05,IF(OR($F35="Efectivo",$F35="Transferencia"),0.07,0))) -> 0.05 | L35: =IF($O35<>"Tienda",0,$J35*$K35) -> 1016.0452 | M35: =E35-G35-I35-L35 -> 19304.858 | N35: michelle | O35: Tienda
